Workbook

Sheet LEGO_sets
B3: LEGO sets | F3: Suma | G3: =sum(K22:K1073) -> 18828.16 | J3: Počet | K3: =COUNT(K22:K1073) -> 125 | N3: Porovnanie cien
B8: Majiteľ | C8: Suma | D8: Počet | F8: Platba | G8: Suma | H8: Počet | J8: Séria | K8: Suma | L8: Počet | N8: Kúpa | O8: Suma | P8: Počet
B9: Ľuboš | C9: =SUMIFS(K22:K1073,N22:N1073,B9) -> 15693.33 | D9: =COUNTIFS($N$22:$N$1073,B9) -> 91 | F9: Ľuboš | G9: =SUMIFS($K$22:$K$1073,$O$22:$O$1073,F9) -> 14124.36 | H9: =COUNTIFS($O$22:$O$1073,F9) -> 79 | J9: {=SORT(S21:U31,2,FALSE)} -> Star Wars | K9: 10973.99 | L9: 68 | N9: {=SORT(UNIQUE(YEAR(L22:L1073)),1,FALSE)} -> 2026 | O9: =IF(SUMIFS($K$22:$K$1178,$P$22:$P$1178,N9)=0,"",SUMIFS($K$22:$K$1178,$P$22:$P$1178,N9)) -> 791.35 | P9: =IF(N9=1899,"", IF(COUNTIFS($P$22:$P$1178,N9)=0,"",COUNTIFS($P$22:$P$1178,N9))) -> 14
B10: Domča | C10: =SUMIFS(K22:K1073,N22:N1073,B10) -> 3134.83 | D10: =COUNTIFS($N$22:$N$1073,B10) -> 34 | F10: Domča | G10: =SUMIFS($K$22:$K$1073,$O$22:$O$1073,F10) -> 4703.8 | H10: =COUNTIFS($O$22:$O$1073,F10) -> 46 | J10: Technic | K10: 3416.43 | L10: 15 | N10: 2025 | O10: =IF(SUMIFS($K$22:$K$1178,$P$22:$P$1178,N10)=0,"",SUMIFS($K$22:$K$1178,$P$22:$P$1178,N10)) -> 6513.63 | P10: =IF(N10=1899,"", IF(COUNTIFS($P$22:$P$1178,N10)=0,"",COUNTIFS($P$22:$P$1178,N10))) -> 54
B11: Spolu | C11: =C9+C10 -> 18828.16 | D11: =D9+D10 -> 125 | F11: Spolu | G11: =G9+G10 -> 18828.16 | H11: =H9+H10 -> 125 | J11: Icons | K11: 1899.68 | L11: 14 | N11: 2024 | O11: =IF(SUMIFS($K$22:$K$1178,$P$22:$P$1178,N11)=0,"",SUMIFS($K$22:$K$1178,$P$22:$P$1178,N11)) -> 10914.43 | P11: =IF(N11=1899,"", IF(COUNTIFS($P$22:$P$1178,N11)=0,"",COUNTIFS($P$22:$P$1178,N11))) -> 53
B12: =C9/C11 -> 0.83350311 | F12: =G9/G11 -> 0.75017208 | J12: DC | K12: 954.8 | L12: 4 | N12: 2023 | O12: =IF(SUMIFS($K$22:$K$1178,$P$22:$P$1178,N12)=0,"",SUMIFS($K$22:$K$1178,$P$22:$P$1178,N12)) -> 287.12 | P12: =IF(N12=1899,"", IF(COUNTIFS($P$22:$P$1178,N12)=0,"",COUNTIFS($P$22:$P$1178,N12))) -> 1
J13: Harry Potter | K13: 837.07 | L13: 12 | N13: 2022 | O13: =IF(SUMIFS($K$22:$K$1178,$P$22:$P$1178,N13)=0,"",SUMIFS($K$22:$K$1178,$P$22:$P$1178,N13)) -> 136.63 | P13: =IF(N13=1899,"", IF(COUNTIFS($P$22:$P$1178,N13)=0,"",COUNTIFS($P$22:$P$1178,N13))) -> 1
J14: Marvel | K14: 559.9 | L14: 3 | N14: 2014 | O14: =IF(SUMIFS($K$22:$K$1178,$P$22:$P$1178,N14)=0,"",SUMIFS($K$22:$K$1178,$P$22:$P$1178,N14)) -> 185 | P14: =IF(N14=1899,"", IF(COUNTIFS($P$22:$P$1178,N14)=0,"",COUNTIFS($P$22:$P$1178,N14))) -> 2
J15: Extra | K15: 130.31 | L15: 7 | N15: 1899 | O15: =IF(SUMIFS($K$22:$K$1178,$P$22:$P$1178,N15)=0,"",SUMIFS($K$22:$K$1178,$P$22:$P$1178,N15)) | P15: =IF(N15=1899,"", IF(COUNTIFS($P$22:$P$1178,N15)=0,"",COUNTIFS($P$22:$P$1178,N15)))
J16: Speed | K16: 55.98 | L16: 2 | O16: =IF(SUMIFS($K$22:$K$1178,$P$22:$P$1178,N16)=0,"",SUMIFS($K$22:$K$1178,$P$22:$P$1178,N16)) | P16: =IF(N16=1899,"", IF(COUNTIFS($P$22:$P$1178,N16)=0,"",COUNTIFS($P$22:$P$1178,N16)))
K17: 0 | L17: 0 | O17: =IF(SUMIFS($K$22:$K$1178,$P$22:$P$1178,N17)=0,"",SUMIFS($K$22:$K$1178,$P$22:$P$1178,N17)) | P17: =IF(N17=1899,"", IF(COUNTIFS($P$22:$P$1178,N17)=0,"",COUNTIFS($P$22:$P$1178,N17)))
K18: 0 | L18: 0 | O18: =IF(SUMIFS($K$22:$K$1178,$P$22:$P$1178,N18)=0,"",SUMIFS($K$22:$K$1178,$P$22:$P$1178,N18)) | P18: =IF(N18=1899,"", IF(COUNTIFS($P$22:$P$1178,N18)=0,"",COUNTIFS($P$22:$P$1178,N18)))
K19: 0 | L19: 0
B21: Séria | D21: Set | F21: Názov setu | H21: Minifigs | J21: Rok setu | K21: Cena | L21: Dátum | N21: Majiteľ | O21: Platba | P21: TECH | S21: {=SORT(UNIQUE(B22:B1178))} -> DC | T21: =IF(SUMIFS($K$22:$K$1178,$B$22:$B$1178,S21)=0,0,SUMIFS($K$22:$K$1178,$B$22:$B$1178,S21)) -> 954.8 | U21: =IF(COUNTIFS($B$22:$B$1178,S21)=0,0,COUNTIFS($B$22:$B$1178,S21)) -> 4
B22: DC | D22: 76139 | F22: Batmobil 1989 | H22: =COUNTIFS(Minifigures!$C$22:$C$1137,D22) -> 3 | J22: 2019 | K22: 380 | L22: 45303 | N22: Ľuboš | O22: Ľuboš | P22: =YEAR(L22) -> 2024 | S22: Extra | T22: =IF(SUMIFS($K$22:$K$1178,$B$22:$B$1178,S22)=0,0,SUMIFS($K$22:$K$1178,$B$22:$B$1178,S22)) -> 130.31 | U22: =IF(COUNTIFS($B$22:$B$1178,S22)=0,0,COUNTIFS($B$22:$B$1178,S22)) -> 7
B23: DC | D23: 76161 | F23: Batwing 1989 | H23: =COUNTIFS(Minifigures!$C$22:$C$1137,D23) -> 3 | J23: 2020 | K23: 230 | L23: 45334 | N23: Ľuboš | O23: Ľuboš | P23: =YEAR(L23) -> 2024 | S23: Harry Potter | T23: =IF(SUMIFS($K$22:$K$1178,$B$22:$B$1178,S23)=0,0,SUMIFS($K$22:$K$1178,$B$22:$B$1178,S23)) -> 837.07 | U23: =IF(COUNTIFS($B$22:$B$1178,S23)=0,0,COUNTIFS($B$22:$B$1178,S23)) -> 12
B24: DC | D24: 76240 | F24: Tumbler | H24: =COUNTIFS(Minifigures!$C$22:$C$1137,D24) -> 2 | J24: 2021 | K24: 199.9 | L24: 45318 | N24: Ľuboš | O24: Ľuboš | P24: =YEAR(L24) -> 2024 | S24: Icons | T24: =IF(SUMIFS($K$22:$K$1178,$B$22:$B$1178,S24)=0,0,SUMIFS($K$22:$K$1178,$B$22:$B$1178,S24)) -> 1899.68 | U24: =IF(COUNTIFS($B$22:$B$1178,S24)=0,0,COUNTIFS($B$22:$B$1178,S24)) -> 14
B25: DC | D25: 76328 | F25: Batmobil z klasického TV seriálu | H25: =COUNTIFS(Minifigures!$C$22:$C$1137,D25) -> 1 | J25: 2024 | K25: 144.9 | L25: 45566 | N25: Ľuboš | O25: Domča | P25: =YEAR(L25) -> 2024 | S25: Marvel | T25: =IF(SUMIFS($K$22:$K$1178,$B$22:$B$1178,S25)=0,0,SUMIFS($K$22:$K$1178,$B$22:$B$1178,S25)) -> 559.9 | U25: =IF(COUNTIFS($B$22:$B$1178,S25)=0,0,COUNTIFS($B$22:$B$1178,S25)) -> 3
B26: Extra | D26: 40291 | F26: Kreatívne osobnosti (Hans Christian Andersen) | H26: =COUNTIFS(Minifigures!$C$22:$C$1137,D26) -> 2 | J26: 2018 | K26: 25 | L26: 45839 | N26: Domča | O26: Domča | P26: =YEAR(L26) -> 2025 | S26: Speed | T26: =IF(SUMIFS($K$22:$K$1178,$B$22:$B$1178,S26)=0,0,SUMIFS($K$22:$K$1178,$B$22:$B$1178,S26)) -> 55.98 | U26: =IF(COUNTIFS($B$22:$B$1178,S26)=0,0,COUNTIFS($B$22:$B$1178,S26)) -> 2
B27: Extra | D27: 40410 | F27: Pocta Charlesovi Dickensovi | H27: =COUNTIFS(Minifigures!$C$22:$C$1137,D27) -> 3 | J27: 2020 | K27: 55.31 | L27: 45871 | N27: Domča | O27: Domča | P27: =YEAR(L27) -> 2025 | S27: Star Wars | T27: =IF(SUMIFS($K$22:$K$1178,$B$22:$B$1178,S27)=0,0,SUMIFS($K$22:$K$1178,$B$22:$B$1178,S27)) -> 10973.99 | U27: =IF(COUNTIFS($B$22:$B$1178,S27)=0,0,COUNTIFS($B$22:$B$1178,S27)) -> 68
B28: Extra | D28: 40690 | F28: Pocta knihám Julesa Vernea | H28: =COUNTIFS(Minifigures!$C$22:$C$1137,D28) -> 1 | J28: 2024 | K28: 50 | L28: 45474 | N28: Domča | O28: Ľuboš | P28: =YEAR(L28) -> 2024 | S28: Technic | T28: =IF(SUMIFS($K$22:$K$1178,$B$22:$B$1178,S28)=0,0,SUMIFS($K$22:$K$1178,$B$22:$B$1178,S28)) -> 3416.43 | U28: =IF(COUNTIFS($B$22:$B$1178,S28)=0,0,COUNTIFS($B$22:$B$1178,S28)) -> 15
B29: Extra | D29: 40712 | F29: Štartovacia plocha pre mikroraketu | H29: =COUNTIFS(Minifigures!$C$22:$C$1137,D29) -> 2 | J29: 2024 | K29: 0 | L29: 45505 | N29: Ľuboš | O29: Ľuboš | P29: =YEAR(L29) -> 2024 | T29: =IF(SUMIFS($K$22:$K$1178,$B$22:$B$1178,S29)=0,0,SUMIFS($K$22:$K$1178,$B$22:$B$1178,S29)) -> 0 | U29: =IF(COUNTIFS($B$22:$B$1178,S29)=0,0,COUNTIFS($B$22:$B$1178,S29)) -> 0
B30: Extra | D30: 40766 | F30: Pocta knihám Jane Austenovej | H30: =COUNTIFS(Minifigures!$C$22:$C$1137,D30) -> 1 | J30: 2025 | K30: 0 | L30: 45839 | N30: Domča | O30: Ľuboš | P30: =YEAR(L30) -> 2025 | T30: =IF(SUMIFS($K$22:$K$1178,$B$22:$B$1178,S30)=0,0,SUMIFS($K$22:$K$1178,$B$22:$B$1178,S30)) -> 0 | U30: =IF(COUNTIFS($B$22:$B$1178,S30)=0,0,COUNTIFS($B$22:$B$1178,S30)) -> 0
B31: Extra | D31: 40767 | F31: Zväčšený malý astronaut | H31: =COUNTIFS(Minifigures!$C$22:$C$1137,D31) -> 0 | J31: 2025 | K31: 0 | L31: 45870 | N31: Ľuboš | O31: Ľuboš | P31: =YEAR(L31) -> 2025 | T31: =IF(SUMIFS($K$22:$K$1178,$B$22:$B$1178,S31)=0,0,SUMIFS($K$22:$K$1178,$B$22:$B$1178,S31)) -> 0 | U31: =IF(COUNTIFS($B$22:$B$1178,S31)=0,0,COUNTIFS($B$22:$B$1178,S31)) -> 0
B32: Extra | D32: 40784 | F32: Africka savana Diorama | H32: =COUNTIFS(Minifigures!$C$22:$C$1137,D32) -> 0 | J32: 2025 | K32: 0 | L32: 45839 | N32: Ľuboš | O32: Ľuboš | P32: =YEAR(L32) -> 2025
B33: Harry Potter | D33: 30651 | F33: Metlobalový tréning | H33: =COUNTIFS(Minifigures!$C$22:$C$1137,D33) -> 1 | J33: 2023 | K33: 5 | L33: 45536 | N33: Domča | O33: Ľuboš | P33: =YEAR(L33) -> 2024
B34: Harry Potter | D34: 30677 | F34: Draco v Zakázanom lese | H34: =COUNTIFS(Minifigures!$C$22:$C$1137,D34) -> 1 | J34: 2024 | K34: 5 | L34: 45536 | N34: Domča | O34: Ľuboš | P34: =YEAR(L34) -> 2024
B35: Harry Potter | D35: 75979 | F35: Hedviga | H35: =COUNTIFS(Minifigures!$C$22:$C$1137,D35) -> 1 | J35: 2020 | K35: 57.9 | L35: 45419 | N35: Domča | O35: Ľuboš | P35: =YEAR(L35) -> 2024
B36: Harry Potter | D36: 76408 | F36: Grimmwauldovo námeste č. 12 | H36: =COUNTIFS(Minifigures!$C$22:$C$1137,D36) -> 9 | J36: 2022 | K36: 167.7 | L36: 45332 | N36: Domča | O36: Ľuboš | P36: =YEAR(L36) -> 2024
B37: Harry Potter | D37: 76414 | F37: Expecto Patronum | H37: =COUNTIFS(Minifigures!$C$22:$C$1137,D37) -> 4 | J37: 2023 | K37: 56.9 | L37: 45474 | N37: Domča | O37: Domča | P37: =YEAR(L37) -> 2024
B38: Harry Potter | D38: 76414 | F38: Expecto Patronum | H38: =COUNTIFS(Minifigures!$C$22:$C$1137,D38) -> 4 | J38: 2023 | K38: 56.9 | L38: 45474 | N38: Domča | O38: Domča | P38: =YEAR(L38) -> 2024
B39: Harry Potter | D39: 76419 | F39: Rokfortský hrad | H39: =COUNTIFS(Minifigures!$C$22:$C$1137,D39) -> 1 | J39: 2023 | K39: 139.9 | L39: 45314 | N39: Domča | O39: Ľuboš | P39: =YEAR(L39) -> 2024
B40: Harry Potter | D40: 76424 | F40: Lietajúce auto Ford Anglia | H40: =COUNTIFS(Minifigures!$C$22:$C$1137,D40) -> 2 | J40: 2024 | K40: 14.99 | L40: 45696 | N40: Domča | O40: Domča | P40: =YEAR(L40) -> 2025
B41: Harry Potter | D41: 76444 | F41: Čarodejnícke obchody Šikmá ulička | H41: =COUNTIFS(Minifigures!$C$22:$C$1137,D41) -> 0 | J41: 2025 | K41: 169.9 | L41: 45720 | N41: Domča | O41: Domča | P41: =YEAR(L41) -> 2025
B42: Harry Potter | D42: 76450 | F42: Knižná zarážka: Rokfortský expres | H42: =COUNTIFS(Minifigures!$C$22:$C$1137,D42) -> 2 | J42: 2025 | K42: 84.99 | L42: 45839 | N42: Domča | O42: Ľuboš | P42: =YEAR(L42) -> 2025
B43: Harry Potter | D43: 76459 | F43: Hagrid™ a Harryho útek z Privátnej cesty | H43: =COUNTIFS(Minifigures!$C$22:$C$1137,D43) -> 4 | J43: 2026 | K43: 16.9 | L43: 46143 | N43: Domča | O43: Domča | P43: =YEAR(L43) -> 2026
... B130: Star Wars | D130: 75452 | F130: Astromechanický droid BB-8™ | H130: =COUNTIFS(Minifigures!$C$22:$C$1137,D130) -> 1 | J130: 2026 | K130: 76.2 | L130: 46028 | N130: Domča | O130: Domča | P130: =YEAR(L130) -> 2026
B131: Star Wars | D131: N/A | F131: SW collect global | H131: =COUNTIFS(Minifigures!$C$22:$C$1137,D131) -> 0 | J131: 2024 | K131: 0 | L131: 45415 | N131: Ľuboš | O131: Domča | P131: =YEAR(L131) -> 2024
B132: Technic | D132: 8293 | F132: Motorová súprava | H132: =COUNTIFS(Minifigures!$C$22:$C$1137,D132) -> 0 | J132: 2008 | K132: 35 | L132: 41821 | N132: Ľuboš | O132: Domča | P132: =YEAR(L132) -> 2014
B133: Technic | D133: 9395 | F133: Odťahový pickup | H133: =COUNTIFS(Minifigures!$C$22:$C$1137,D133) -> 0 | J133: 2012 | K133: 150 | L133: 41821 | N133: Ľuboš | O133: Domča | P133: =YEAR(L133) -> 2014
...

Sheet Minifigures
B3: Figúrky | D3: Použité + 80 % Nové | F3: Nové | I3: # | K3: =COUNT(C23:C1137) -> 367 | N3: Minifigs Price
D4: =SUM(H23:H1137)+0.8*SUMIFS(I23:I1137,H23:H1137,"") -> 4284.476 | F4: =SUM(I23:I1137) -> 4769.572
B8: Set | D8: Použitý | F8: Nový | H8: Počet | K8: Set | L8: Najdrahšia figúrka (Nový) | O8: Použitý | P8: Nový
B9: {=SORT(R9:X19,7,false)} -> Star Wars | D9: 3072.53 | F9: 3408.113 | H9: 260 | K9: {=sort(S22:X32,6,False)} -> Star Wars | L9: Boba Fett | O9: 85.09 | P9: 135.15 | R9: {=SORT(UNIQUE(B23:B1137))} -> DC | T9: =IF(SUMIFS($H$23:$H$1137,$B$23:$B$1137,R9)=0,0,SUMIFS($H$23:$H$1137,$B$23:$B$1137,R9)) -> 209.74 | V9: =IF(SUMIFS($I$23:$I$1137,$B$23:$B$1137,R9)=0,0,SUMIFS($I$23:$I$1137,$B$23:$B$1137,R9)) -> 236.87 | X9: =IF(COUNTIFS($B$23:$B$1137,R9)=0,0,COUNTIFS($B$23:$B$1137,R9)) -> 9
B10: Icons | D10: 630.72 | F10: 721.58 | H10: 38 | K10: Icons | L10: Ensign Ro Laren | O10: 86.26 | P10: 70.28 | R10: Extra | T10: =IF(SUMIFS($H$23:$H$1137,$B$23:$B$1137,R10)=0,0,SUMIFS($H$23:$H$1137,$B$23:$B$1137,R10)) -> 55.46 | V10: =IF(SUMIFS($I$23:$I$1137,$B$23:$B$1137,R10)=0,0,SUMIFS($I$23:$I$1137,$B$23:$B$1137,R10)) -> 62.41 | X10: =IF(COUNTIFS($B$23:$B$525,R10)=0,0,COUNTIFS($B$23:$B$525,R10)) -> 9
B11: Harry Potter | D11: 112.13 | F11: 153.79 | H11: 27 | K11: DC | L11: Batman | O11: 37.58 | P11: 37.58 | R11: Harry Potter | T11: =IF(SUMIFS($H$23:$H$1137,$B$23:$B$1137,R11)=0,0,SUMIFS($H$23:$H$1137,$B$23:$B$1137,R11)) -> 112.13 | V11: =IF(SUMIFS($I$23:$I$1137,$B$23:$B$1137,R11)=0,0,SUMIFS($I$23:$I$1137,$B$23:$B$1137,R11)) -> 153.79 | X11: =IF(COUNTIFS($B$23:$B$525,R11)=0,0,COUNTIFS($B$23:$B$525,R11)) -> 27
B12: Marvel | D12: 144.2 | F12: 151.899 | H12: 20 | K12: Marvel | L12: Drax | O12: 19.97 | P12: 22.65 | R12: Icons | T12: =IF(SUMIFS($H$23:$H$1137,$B$23:$B$1137,R12)=0,0,SUMIFS($H$23:$H$1137,$B$23:$B$1137,R12)) -> 630.72 | V12: =IF(SUMIFS($I$23:$I$1137,$B$23:$B$1137,R12)=0,0,SUMIFS($I$23:$I$1137,$B$23:$B$1137,R12)) -> 721.58 | X12: =IF(COUNTIFS($B$23:$B$525,R12)=0,0,COUNTIFS($B$23:$B$525,R12)) -> 38
B13: DC | D13: 209.74 | F13: 236.87 | H13: 9 | K13: Harry Potter | L13: Ron Weasly | O13: 10.24 | P13: 16 | R13: Marvel | T13: =IF(SUMIFS($H$23:$H$1137,$B$23:$B$1137,R13)=0,0,SUMIFS($H$23:$H$1137,$B$23:$B$1137,R13)) -> 144.2 | V13: =IF(SUMIFS($I$23:$I$1137,$B$23:$B$1137,R13)=0,0,SUMIFS($I$23:$I$1137,$B$23:$B$1137,R13)) -> 151.899 | X13: =IF(COUNTIFS($B$23:$B$525,R13)=0,0,COUNTIFS($B$23:$B$525,R13)) -> 20
B14: Extra | D14: 55.46 | F14: 62.41 | H14: 9 | K14: Speed | L14: Joshua Pearce | P14: 11.9 | R14: Speed | T14: =IF(SUMIFS($H$23:$H$1137,$B$23:$B$1137,R14)=0,0,SUMIFS($H$23:$H$1137,$B$23:$B$1137,R14)) -> 12.32 | V14: =IF(SUMIFS($I$23:$I$1137,$B$23:$B$1137,R14)=0,0,SUMIFS($I$23:$I$1137,$B$23:$B$1137,R14)) -> 34.91 | X14: =IF(COUNTIFS($B$23:$B$525,R14)=0,0,COUNTIFS($B$23:$B$525,R14)) -> 4
B15: Speed | D15: 12.32 | F15: 34.91 | H15: 4 | K15: Extra | L15: Jane Austenová | O15: 14.62 | P15: 11.7 | R15: Star Wars | T15: =IF(SUMIFS($H$23:$H$1137,$B$23:$B$1137,R15)=0,0,SUMIFS($H$23:$H$1137,$B$23:$B$1137,R15)) -> 3072.53 | V15: =IF(SUMIFS($I$23:$I$1137,$B$23:$B$1137,R15)=0,0,SUMIFS($I$23:$I$1137,$B$23:$B$1137,R15)) -> 3408.113 | X15: =IF(COUNTIFS($B$23:$B$525,R15)=0,0,COUNTIFS($B$23:$B$525,R15)) -> 260
D16: 0 | F16: 0 | H16: 0 | P16: 0 | T16: =IF(SUMIFS($H$23:$H$1137,$B$23:$B$1137,R16)=0,0,SUMIFS($H$23:$H$1137,$B$23:$B$1137,R16)) -> 0 | V16: =IF(SUMIFS($I$23:$I$1137,$B$23:$B$1137,R16)=0,0,SUMIFS($I$23:$I$1137,$B$23:$B$1137,R16)) -> 0 | X16: =IF(COUNTIFS($B$23:$B$525,R16)=0,0,COUNTIFS($B$23:$B$525,R16)) -> 0
D17: 0 | F17: 0 | H17: 0 | P17: 0 | T17: =IF(SUMIFS($H$23:$H$1137,$B$23:$B$1137,R17)=0,0,SUMIFS($H$23:$H$1137,$B$23:$B$1137,R17)) -> 0 | V17: =IF(SUMIFS($I$23:$I$1137,$B$23:$B$1137,R17)=0,0,SUMIFS($I$23:$I$1137,$B$23:$B$1137,R17)) -> 0 | X17: =IF(COUNTIFS($B$23:$B$525,R17)=0,0,COUNTIFS($B$23:$B$525,R17)) -> 0
D18: 0 | F18: 0 | H18: 0 | P18: 0 | T18: =IF(SUMIFS($H$23:$H$1137,$B$23:$B$1137,R18)=0,0,SUMIFS($H$23:$H$1137,$B$23:$B$1137,R18)) -> 0 | V18: =IF(SUMIFS($I$23:$I$1137,$B$23:$B$1137,R18)=0,0,SUMIFS($I$23:$I$1137,$B$23:$B$1137,R18)) -> 0 | X18: =IF(COUNTIFS($B$23:$B$525,R18)=0,0,COUNTIFS($B$23:$B$525,R18)) -> 0
D19: 0 | F19: 0 | H19: 0 | P19: 0 | T19: =IF(SUMIFS($H$23:$H$1137,$B$23:$B$1137,R19)=0,0,SUMIFS($H$23:$H$1137,$B$23:$B$1137,R19)) -> 0 | V19: =IF(SUMIFS($I$23:$I$1137,$B$23:$B$1137,R19)=0,0,SUMIFS($I$23:$I$1137,$B$23:$B$1137,R19)) -> 0 | X19: =IF(COUNTIFS($B$23:$B$525,R19)=0,0,COUNTIFS($B$23:$B$525,R19)) -> 0
B20: Total | D20: =sum(D9:E19) -> 4237.1 | F20: =sum(F9:G19) -> 4769.572 | H20: =sum(H9:I19) -> 367 | K20: Total | O20: =sum(O9:O19) -> 253.76 | P20: =sum(P9:P19) -> 305.26
K21: T
B22: Séria | C22: Set | D22: Figúrka | G22: Označenie | H22: Použitý | I22: Nový | J22: Collectorka | L22: Počet | M22: Poznámka | S22: {=SORT(UNIQUE(B23:B1137))} -> DC | T22: =IFERROR(XLOOKUP(X22,$I$23:$I$1137,$D$23:$D$1137),"") -> Batman | W22: =IFERROR(XLOOKUP(X22,$I$23:$I$1137,$H$23:$H$1137),"") -> 37.58 | X22: =MAXIFS($I$23:$I$1137,$B$23:$B$1137,S22) -> 37.58
B23: DC | C23: 76139 | D23: Joker | G23: SH0608 | H23: 28.02 | I23: 34.08 | J23: FALSE | L23: =IF(G23="","", COUNTIFS($G$23:$G$1137,G23)) -> 1 | S23: Extra | T23: =IFERROR(XLOOKUP(X23,$I$23:$I$1137,$D$23:$D$1137),"") -> Jane Austenová | W23: =IFERROR(XLOOKUP(X23,$I$23:$I$1137,$H$23:$H$1137),"") -> 14.62 | X23: =MAXIFS($I$23:$I$1137,$B$23:$B$1137,S23) -> 11.7
B24: DC | C24: 76139 | D24: Batman | G24: SH0607 | H24: 24.82 | I24: 26.77 | J24: FALSE | L24: =IF(G24="","", COUNTIFS($G$23:$G$1137,G24)) -> 2 | S24: Harry Potter | T24: =IFERROR(XLOOKUP(X24,$I$23:$I$1137,$D$23:$D$1137),"") -> Ron Weasly | W24: =IFERROR(XLOOKUP(X24,$I$23:$I$1137,$H$23:$H$1137),"") -> 10.24 | X24: =MAXIFS($I$23:$I$1137,$B$23:$B$1137,S24) -> 16
B25: DC | C25: 76139 | D25: Vicki Vale | G25: SH0609 | H25: 10.35 | I25: 14.35 | J25: FALSE | L25: =IF(G25="","", COUNTIFS($G$23:$G$1137,G25)) -> 1 | S25: Icons | T25: =IFERROR(XLOOKUP(X25,$I$23:$I$1137,$D$23:$D$1137),"") -> Ensign Ro Laren | W25: =IFERROR(XLOOKUP(X25,$I$23:$I$1137,$H$23:$H$1137),"") -> 86.26 | X25: =MAXIFS($I$23:$I$1137,$B$23:$B$1137,S25) -> 70.28
B26: DC | C26: 76161 | D26: Batman | G26: SH0607 | H26: 24.82 | I26: 26.77 | J26: FALSE | L26: =IF(G26="","", COUNTIFS($G$23:$G$1137,G26)) -> 2 | S26: Marvel | T26: =IFERROR(XLOOKUP(X26,$I$23:$I$1137,$D$23:$D$1137),"") -> Drax | W26: =IFERROR(XLOOKUP(X26,$I$23:$I$1137,$H$23:$H$1137),"") -> 19.97 | X26: =MAXIFS($I$23:$I$1137,$B$23:$B$1137,S26) -> 22.65
B27: DC | C27: 76161 | D27: Joker | G27: SH0671 | H27: 24.96 | I27: 25.22 | J27: FALSE | L27: =IF(G27="","", COUNTIFS($G$23:$G$1137,G27)) -> 1 | S27: Speed | T27: =IFERROR(XLOOKUP(X27,$I$23:$I$1137,$D$23:$D$1137),"") -> Joshua Pearce | W27: =IFERROR(XLOOKUP(X27,$I$23:$I$1137,$H$23:$H$1137),"") | X27: =MAXIFS($I$23:$I$1137,$B$23:$B$1137,S27) -> 11.9
B28: DC | C28: 76161 | D28: Lawrence the Boombox Goon | G28: SH0672 | H28: 14.88 | I28: 18.34 | J28: FALSE | L28: =IF(G28="","", COUNTIFS($G$23:$G$1137,G28)) -> 1 | S28: Star Wars | T28: =IFERROR(XLOOKUP(X28,$I$23:$I$1137,$D$23:$D$1137),"") -> Boba Fett | W28: =IFERROR(XLOOKUP(X28,$I$23:$I$1137,$H$23:$H$1137),"") -> 85.09 | X28: =MAXIFS($I$23:$I$1137,$B$23:$B$1137,S28) -> 135.15
B29: DC | C29: 76240 | D29: Joker | G29: SH0972 | H29: 26.08 | I29: 31.35 | J29: FALSE | L29: =IF(G29="","", COUNTIFS($G$23:$G$1137,G29)) -> 1 | T29: =IFERROR(XLOOKUP(X29,$I$23:$I$1137,$D$23:$D$1137),"") | W29: =IFERROR(XLOOKUP(X29,$I$23:$I$1137,$H$23:$H$1137),"") | X29: =MAXIFS($I$23:$I$1137,$B$23:$B$1137,S29) -> 0
B30: DC | C30: 76240 | D30: Batman | G30: SH0791 | H30: 18.23 | I30: 22.41 | J30: FALSE | L30: =IF(G30="","", COUNTIFS($G$23:$G$1137,G30)) -> 1 | T30: =IFERROR(XLOOKUP(X30,$I$23:$I$1137,$D$23:$D$1137),"") | W30: =IFERROR(XLOOKUP(X30,$I$23:$I$1137,$H$23:$H$1137),"") | X30: =MAXIFS($I$23:$I$1137,$B$23:$B$1137,S30) -> 0
B31: DC | C31: 76328 | D31: Batman | G31: SH0986 | H31: 37.58 | I31: 37.58 | J31: FALSE | L31: =IF(G31="","", COUNTIFS($G$23:$G$1137,G31)) -> 1 | T31: =IFERROR(XLOOKUP(X31,$I$23:$I$1137,$D$23:$D$1137),"") | W31: =IFERROR(XLOOKUP(X31,$I$23:$I$1137,$H$23:$H$1137),"") | X31: =MAXIFS($I$23:$I$1137,$B$23:$B$1137,S31) -> 0
B32: Extra | C32: 40291 | D32: Hans CHristian Andersen | G32: GEN107 | H32: 2 | I32: 4.05 | J32: FALSE | L32: =IF(G32="","", COUNTIFS($G$23:$G$1137,G32)) -> 1 | T32: =IFERROR(XLOOKUP(X32,$I$23:$I$1137,$D$23:$D$1137),"") | W32: =IFERROR(XLOOKUP(X32,$I$23:$I$1137,$H$23:$H$1137),"") | X32: =MAXIFS($I$23:$I$1137,$B$23:$B$1137,S32) -> 0
B33: Extra | C33: 40291 | D33: Chlapec s praclíkom | G33: GEN108 | H33: 1.91 | I33: 1.51 | J33: FALSE | L33: =IF(G33="","", COUNTIFS($G$23:$G$1137,G33)) -> 1
B34: Extra | C34: 40410 | D34: Ebenezer Scrooge | G34: HOL211 | H34: 6.78 | I34: 8.71 | J34: FALSE | L34: =IF(G34="","", COUNTIFS($G$23:$G$1137,G34)) -> 1
B35: Extra | C35: 40410 | D35: Bob Cratchit | G35: HOL213 | H35: 3.07 | I35: 4.49 | J35: FALSE | L35: =IF(G35="","", COUNTIFS($G$23:$G$1137,G35)) -> 1
B36: Extra | C36: 40410 | D36: Tiny Tim | G36: HOL212 | H36: 3.31 | I36: 4.01 | J36: FALSE | L36: =IF(G36="","", COUNTIFS($G$23:$G$1137,G36)) -> 1 | T36: {=IFERROR(XLOOKUP(X36,$I$23:$I$1137,$D$23:$D$1137),"")} | W36: {=IFERROR(XLOOKUP(X36,$I$23:$I$1137,$H$23:$H$1137),"")} | X36: =MAXIFS($I$23:$I$1137,$B$23:$B$1137,S36) -> 0
B37: Extra | C37: 40690 | D37: Jules Verne | G37: GEN183 | H37: 6.36 | I37: 7.3 | J37: FALSE | L37: =IF(G37="","", COUNTIFS($G$23:$G$1137,G37)) -> 1
B38: Extra | C38: 40712 | D38: Classic Space, Little - White | G38: SP141 | H38: 11.05 | I38: 11.24 | J38: FALSE | L38: =IF(G38="","", COUNTIFS($G$23:$G$1137,G38)) -> 1
B39: Extra | C39: 40712 | D39: Classic Space, Little - Blue | G39: SP140 | H39: 6.36 | I39: 9.4 | J39: FALSE | L39: =IF(G39="","", COUNTIFS($G$23:$G$1137,G39)) -> 1
B40: Extra | C40: 40766 | D40: Jane Austenová | G40: GEN194 | H40: 14.62 | I40: 11.7 | J40: FALSE | L40: =IF(G40="","", COUNTIFS($G$23:$G$1137,G40)) -> 1
B41: Harry Potter | C41: 30651 | D41: Cho Chang | G41: HP418 | H41: 1.99 | I41: 2.12 | J41: FALSE | L41: =IF(G41="","", COUNTIFS($G$23:$G$1137,G41)) -> 1
B42: Harry Potter | C42: 30677 | D42: Draco Malfoy | G42: HP254 | H42: 1.75 | I42: 1.83 | J42: FALSE | L42: =IF(G42="","", COUNTIFS($G$23:$G$1137,G42)) -> 1 | M42: S lampášom svietiacim v tme
B43: Harry Potter | C43: 75979 | D43: Harry Potter | G43: HP237 | H43: 1.96 | I43: 3.69 | J43: FALSE | L43: =IF(G43="","", COUNTIFS($G$23:$G$1137,G43)) -> 1 | M43: Hedvig, Harry's owl
B44: Harry Potter | C44: 76408 | D44: Kreacher | G44: HP341 | H44: 8.64 | I44: 11.43 | J44: FALSE | L44: =IF(G44="","", COUNTIFS($G$23:$G$1137,G44)) -> 1
B45: Harry Potter | C45: 76408 | D45: Nymphadora Tonks | G45: HP336 | H45: 7.45 | I45: 10.02 | J45: FALSE | L45: =IF(G45="","", COUNTIFS($G$23:$G$1137,G45)) -> 1
...

Sheet wiah_list
B3: WishList | F3: Suma | G3: =sum(K22:K121) -> 6456.82 | J3: Počet | K3: =COUNT(K22:K121) -> 32 | N3: Porovnanie cien
B8: Majiteľ | C8: Suma | D8: Počet | F8: Priorita | G8: Suma | H8: Počet | J8: Séria | K8: Suma | L8: Počet | N8: Kúpa | O8: Suma | P8: Počet
B9: Ľuboš | C9: =SUMIFS(K22:K121,N22:N121,B9) -> 3226.9 | D9: =COUNTIFS($N$22:$N$121,B9) -> 16 | F9: Určite! | G9: =SUMIFS($K$22:$K$121,$O$22:$O$121,F9) -> 3132.89 | H9: =COUNTIFS($O$22:$O$121,F9) -> 20 | J9: {=SORT(S9:U19,2,FALSE)} -> LOTR | K9: 1644.98 | L9: 3 | N9: {=SORT(UNIQUE(YEAR(L22:L1164)),1,FALSE)} -> #VALUE! | O9: =IF(SUMIFS($K$22:$K$1164,$P$22:$P$1164,N9)=0,"",SUMIFS($K$22:$K$1164,$P$22:$P$1164,N9)) | P9: =IF(N9=1899,"", IF(COUNTIFS($P$22:$P$1164,N9)=0,"",COUNTIFS($P$22:$P$1164,N9))) -> #VALUE! | S9: {=SORT(UNIQUE(B22:B1164))} -> Editions | T9: =IF(SUMIFS($K$22:$K$1164,$B$22:$B$1164,S9)=0,0,SUMIFS($K$22:$K$1164,$B$22:$B$1164,S9)) -> 551.94 | U9: =IF(COUNTIFS($B$22:$B$1164,S9)=0,0,COUNTIFS($B$22:$B$1164,S9)) -> 6
B10: Domča | C10: =SUMIFS(K22:K121,N22:N121,B10) -> 3229.92 | D10: =COUNTIFS($N$22:$N$121,B10) -> 16 | F10: Možno... | G10: =SUMIFS($K$22:$K$121,$O$22:$O$121,F10) -> 3323.93 | H10: =COUNTIFS($O$22:$O$121,F10) -> 12 | J10: Star Wars | K10: 1498.98 | L10: 7 | N10: 1899 | O10: =IF(SUMIFS($K$22:$K$1164,$P$22:$P$1164,N10)=0,"",SUMIFS($K$22:$K$1164,$P$22:$P$1164,N10)) -> 1932.92 | P10: =IF(N10=1899,"", IF(COUNTIFS($P$22:$P$1164,N10)=0,"",COUNTIFS($P$22:$P$1164,N10))) | S10: Extra | T10: =IF(SUMIFS($K$22:$K$1164,$B$22:$B$1164,S10)=0,0,SUMIFS($K$22:$K$1164,$B$22:$B$1164,S10)) -> 605 | U10: =IF(COUNTIFS($B$22:$B$1164,S10)=0,0,COUNTIFS($B$22:$B$1164,S10)) -> 8
B11: Spolu | C11: =C9+C10 -> 6456.82 | D11: =D9+D10 -> 32 | F11: Spolu | G11: =G9+G10 -> 6456.82 | H11: =H9+H10 -> 32 | J11: Harry Potter | K11: 709.98 | L11: 2 | O11: =IF(SUMIFS($K$22:$K$1164,$P$22:$P$1164,N11)=0,"",SUMIFS($K$22:$K$1164,$P$22:$P$1164,N11)) | P11: =IF(N11=1899,"", IF(COUNTIFS($P$22:$P$1164,N11)=0,"",COUNTIFS($P$22:$P$1164,N11))) | S11: Harry Potter | T11: =IF(SUMIFS($K$22:$K$1164,$B$22:$B$1164,S11)=0,0,SUMIFS($K$22:$K$1164,$B$22:$B$1164,S11)) -> 709.98 | U11: =IF(COUNTIFS($B$22:$B$1164,S11)=0,0,COUNTIFS($B$22:$B$1164,S11)) -> 2
B12: =C9/C11 -> 0.49976614 | F12: =G9/G11 -> 0.48520634 | J12: Marvel | K12: 639.97 | L12: 3 | O12: =IF(SUMIFS($K$22:$K$1164,$P$22:$P$1164,N12)=0,"",SUMIFS($K$22:$K$1164,$P$22:$P$1164,N12)) | P12: =IF(N12=1899,"", IF(COUNTIFS($P$22:$P$1164,N12)=0,"",COUNTIFS($P$22:$P$1164,N12))) | S12: Icons | T12: =IF(SUMIFS($K$22:$K$1164,$B$22:$B$1164,S12)=0,0,SUMIFS($K$22:$K$1164,$B$22:$B$1164,S12)) -> 355.98 | U12: =IF(COUNTIFS($B$22:$B$1164,S12)=0,0,COUNTIFS($B$22:$B$1164,S12)) -> 3
J13: Extra | K13: 605 | L13: 8 | O13: =IF(SUMIFS($K$22:$K$1164,$P$22:$P$1164,N13)=0,"",SUMIFS($K$22:$K$1164,$P$22:$P$1164,N13)) | P13: =IF(N13=1899,"", IF(COUNTIFS($P$22:$P$1164,N13)=0,"",COUNTIFS($P$22:$P$1164,N13))) | S13: LOTR | T13: =IF(SUMIFS($K$22:$K$1164,$B$22:$B$1164,S13)=0,0,SUMIFS($K$22:$K$1164,$B$22:$B$1164,S13)) -> 1644.98 | U13: =IF(COUNTIFS($B$22:$B$1164,S13)=0,0,COUNTIFS($B$22:$B$1164,S13)) -> 3
J14: Editions | K14: 551.94 | L14: 6 | O14: =IF(SUMIFS($K$22:$K$1164,$P$22:$P$1164,N14)=0,"",SUMIFS($K$22:$K$1164,$P$22:$P$1164,N14)) | P14: =IF(N14=1899,"", IF(COUNTIFS($P$22:$P$1164,N14)=0,"",COUNTIFS($P$22:$P$1164,N14))) | S14: Marvel | T14: =IF(SUMIFS($K$22:$K$1164,$B$22:$B$1164,S14)=0,0,SUMIFS($K$22:$K$1164,$B$22:$B$1164,S14)) -> 639.97 | U14: =IF(COUNTIFS($B$22:$B$1164,S14)=0,0,COUNTIFS($B$22:$B$1164,S14)) -> 3
J15: Technic | K15: 449.99 | L15: 1 | O15: =IF(SUMIFS($K$22:$K$1164,$P$22:$P$1164,N15)=0,"",SUMIFS($K$22:$K$1164,$P$22:$P$1164,N15)) | P15: =IF(N15=1899,"", IF(COUNTIFS($P$22:$P$1164,N15)=0,"",COUNTIFS($P$22:$P$1164,N15))) | S15: Star Wars | T15: =IF(SUMIFS($K$22:$K$1164,$B$22:$B$1164,S15)=0,0,SUMIFS($K$22:$K$1164,$B$22:$B$1164,S15)) -> 1498.98 | U15: =IF(COUNTIFS($B$22:$B$1164,S15)=0,0,COUNTIFS($B$22:$B$1164,S15)) -> 7
J16: Icons | K16: 355.98 | L16: 3 | O16: =IF(SUMIFS($K$22:$K$1164,$P$22:$P$1164,N16)=0,"",SUMIFS($K$22:$K$1164,$P$22:$P$1164,N16)) | P16: =IF(N16=1899,"", IF(COUNTIFS($P$22:$P$1164,N16)=0,"",COUNTIFS($P$22:$P$1164,N16))) | S16: Technic | T16: =IF(SUMIFS($K$22:$K$1164,$B$22:$B$1164,S16)=0,0,SUMIFS($K$22:$K$1164,$B$22:$B$1164,S16)) -> 449.99 | U16: =IF(COUNTIFS($B$22:$B$1164,S16)=0,0,COUNTIFS($B$22:$B$1164,S16)) -> 1
K17: 0 | L17: 0 | O17: =IF(SUMIFS($K$22:$K$1164,$P$22:$P$1164,N17)=0,"",SUMIFS($K$22:$K$1164,$P$22:$P$1164,N17)) | P17: =IF(N17=1899,"", IF(COUNTIFS($P$22:$P$1164,N17)=0,"",COUNTIFS($P$22:$P$1164,N17))) | T17: =IF(SUMIFS($K$22:$K$1164,$B$22:$B$1164,S17)=0,0,SUMIFS($K$22:$K$1164,$B$22:$B$1164,S17)) -> 0 | U17: =IF(COUNTIFS($B$22:$B$1164,S17)=0,0,COUNTIFS($B$22:$B$1164,S17)) -> 0
K18: 0 | L18: 0 | O18: =IF(SUMIFS($K$22:$K$1164,$P$22:$P$1164,N18)=0,"",SUMIFS($K$22:$K$1164,$P$22:$P$1164,N18)) | P18: =IF(N18=1899,"", IF(COUNTIFS($P$22:$P$1164,N18)=0,"",COUNTIFS($P$22:$P$1164,N18))) | T18: =IF(SUMIFS($K$22:$K$1164,$B$22:$B$1164,S18)=0,0,SUMIFS($K$22:$K$1164,$B$22:$B$1164,S18)) -> 0 | U18: =IF(COUNTIFS($B$22:$B$1164,S18)=0,0,COUNTIFS($B$22:$B$1164,S18)) -> 0
K19: 0 | L19: 0 | O19: =IF(SUMIFS($K$22:$K$1164,$P$22:$P$1164,N19)=0,"",SUMIFS($K$22:$K$1164,$P$22:$P$1164,N19)) | P19: =IF(N19=1899,"", IF(COUNTIFS($P$22:$P$1164,N19)=0,"",COUNTIFS($P$22:$P$1164,N19))) | T19: =IF(SUMIFS($K$22:$K$1164,$B$22:$B$1164,S19)=0,0,SUMIFS($K$22:$K$1164,$B$22:$B$1164,S19)) -> 0 | U19: =IF(COUNTIFS($B$22:$B$1164,S19)=0,0,COUNTIFS($B$22:$B$1164,S19)) -> 0
B21: Séria | D21: Set | F21: Názov setu | J21: vydanie | K21: Cena | L21: Pozn | N21: Majiteľ | O21: Priorita | P21: TECH
P22: =YEAR(J22) -> 1899
B23: Extra | D23: 21110 | F23: Výskumné centrum | J23: 2014 | K23: 80 | N23: Domča | O23: Určite! | P23: =YEAR(J23) -> 1905
B24: Extra | D24: 21312 | F24: Ženy z NASA | J24: 2017 | K24: 80 | N24: Domča | O24: Určite! | P24: =YEAR(J24) -> 1905
B25: Extra | D25: 40450 | F25: POCTA AMELII EARHARTOVEJ | J25: 2021 | K25: 50 | N25: Domča | O25: Určite! | P25: =YEAR(J25) -> 1905
B26: Extra | D26: 40530 | F26: Pocta Jane Goodallovej | J26: 2022 | K26: 40 | N26: Domča | O26: Určite! | P26: =YEAR(J26) -> 1905
B27: Extra | D27: 40579 | F27: Eiffelov byt | J27: 2022 | K27: 135 | N27: Domča | O27: Určite! | P27: =YEAR(J27) -> 1905
B28: Extra | D28: 40595 | F28: Pocta Galileovi | J28: 2023 | K28: 95 | N28: Domča | O28: Určite! | P28: =YEAR(J28) -> 1905
B29: Extra | D29: 40729 | F29: Šalupa Shackletona | J29: 2024 | K29: 60 | N29: Domča | O29: Určite! | P29: =YEAR(J29) -> 1905
B30: Marvel | D30: 76325 | F30: Avengers 2: Vek Ultrona Stíhačka Quinjet | J30: 45870 | K30: 124.99 | N30: Domča | O30: Určite! | P30: =YEAR(J30) -> 2025
B31: Marvel | D31: 76354 | F31: Helicarrier S.H.I.E.L.D. | J31: 46174 | K31: 379.99 | N31: Domča | O31: Určite! | P31: =YEAR(J31) -> 2026
P32: =YEAR(J32) -> 1899
B33: Technic | D33: 42232 | F33: Koenigsegg Sadair's Spear | J33: 46204 | K33: 449.99 | N33: Ľuboš | O33: Určite! | P33: =YEAR(J33) -> 2026
B34: Editions | D34: 43014 | F34: Prilba Charles Leclerc zo Scuderia Ferrari HP | J34: 46143 | K34: 91.99 | N34: Ľuboš | O34: Určite! | P34: =YEAR(J34) -> 2026
B35: Editions | D35: 43022 | F35: Prilba Lewis Hamilton zo Scuderia Ferrari HP | J35: 46143 | K35: 91.99 | N35: Ľuboš | O35: Určite! | P35: =YEAR(J35) -> 2026
B36: Star Wars | D36: 75325 | F36: Stiahcka N1 Mandalorian | J36: 44713 | K36: 65.99 | N36: Ľuboš | O36: Určite! | P36: =YEAR(J36) -> 2022
B37: Star Wars | D37: 75347 | F37: Tie bombarder | J37: 44927 | K37: 65.99 | N37: Ľuboš | O37: Určite! | P37: =YEAR(J37) -> 2023
B38: Star Wars | D38: 75354 | F38: Corusantsky delovy cln | J38: 45170 | K38: 154 | L38: vyradený | N38: Ľuboš | O38: Určite! | P38: =YEAR(J38) -> 2023
B39: Star Wars | D39: 75457 | F39: UCS Super Star Destroyer | J39: 46266 | K39: 800 | N39: Ľuboš | O39: Určite! | P39: =YEAR(J39) -> 2026
B40: Editions | F40: helmet senna | K40: 91.99 | N40: Ľuboš | O40: Určite! | P40: =YEAR(J40) -> 1899
B41: Editions | F41: helmet verstapen | K41: 91.99 | N41: Ľuboš | O41: Určite! | P41: =YEAR(J41) -> 1899
B42: Editions | F42: helmet alonso | K42: 91.99 | N42: Ľuboš | O42: Určite! | P42: =YEAR(J42) -> 1899
B43: Editions | F43: helmet norris/piastri | K43: 91.99 | N43: Ľuboš | O43: Určite! | P43: =YEAR(J43) -> 1899
B44: LOTR | D44: 10316 | F44: PÁN PRSTEŇOV – VODODOL | K44: 519.99 | N44: Domča | O44: Možno... | P44: =YEAR(J44) -> 1899
B45: LOTR | D45: 10333 | F45: Pán prsteňov: Barad-dûr™ | K45: 474.99 | N45: Domča | O45: Možno... | P45: =YEAR(J45) -> 1899
B46: Icons | D46: 10354 | F46: Pán prsteňov: Kraj | K46: 279.99 | N46: Domča | O46: Možno... | P46: =YEAR(J46) -> 1899
B47: Extra | D47: 21355 | F47: Vývoj STEM | J47: 2025 | K47: 65 | N47: Domča | O47: Možno... | P47: =YEAR(J47) -> 1905
...
